Traceback (most recent call last):
  File "/home/czq/anaconda3/envs/OpenNCD_env/lib/python3.9/site-packages/torch/__init__.py", line 172, in _load_global_deps
    ctypes.CDLL(lib_path, mode=ctypes.RTLD_GLOBAL)
  File "/home/czq/anaconda3/envs/OpenNCD_env/lib/python3.9/ctypes/__init__.py", line 382, in __init__
    self._handle = _dlopen(self._name, mode)
OSError: libcublas.so.11: cannot open shared object file: No such file or directory

During handling of the above exception, another exception occurred:

Traceback (most recent call last):
  File "/home/czq/workspace/GCD/OpenNCD/main.py", line 3, in <module>
    import torch
  File "/home/czq/anaconda3/envs/OpenNCD_env/lib/python3.9/site-packages/torch/__init__.py", line 217, in <module>
    _load_global_deps()
  File "/home/czq/anaconda3/envs/OpenNCD_env/lib/python3.9/site-packages/torch/__init__.py", line 178, in _load_global_deps
    _preload_cuda_deps()
  File "/home/czq/anaconda3/envs/OpenNCD_env/lib/python3.9/site-packages/torch/__init__.py", line 158, in _preload_cuda_deps
    ctypes.CDLL(cublas_path)
  File "/home/czq/anaconda3/envs/OpenNCD_env/lib/python3.9/ctypes/__init__.py", line 382, in __init__
    self._handle = _dlopen(self._name, mode)
OSError: /home/czq/anaconda3/envs/OpenNCD_env/lib/python3.9/site-packages/nvidia/cublas/lib/libcublas.so.11: cannot open shared object file: No such file or directory
